test.2017-12-31.txt
01:21:07.348 - INFO - [ loggerName: test ] - (Utils.py:33||T=139726611670784)
01:21:07.348 - INFO - [ Main Start! ] - (poloniex.py:318||T=139726611670784)
01:21:08.651 - INFO - [ POLONIEX onConnect ] - (poloniex.py:288||T=139726327990016)
01:21:11.443 - INFO - [ im here ] - (poloniex.py:180||T=139726327990016)
01:21:11.477 - INFO - [ onUpdate POLONIEX Bids USDT_BTC [(12111.76728038, 0.09633076), (12111.76728032, 0.15751211), (12111.76728024, 0.1), (12105.23020657, 0.69006721), (12096.00000003, 0.23508604)] ] - (poloniex.py:202||T=139726327990016)
01:21:11.478 - INFO - [ onUpdate POLONIEX Asks USDT_BTC [(12145.0, 0.65946432), (12149.99999996, 0.66701203), (12149.99999999, 0.94889392), (12150.0, 0.26492714), (12154.99999987, 0.46028193)] ] - (poloniex.py:203||T=139726327990016)
01:21:11.771 - INFO - [ im here ] - (poloniex.py:180||T=139726327990016)
01:21:11.785 - INFO - [ onUpdate POLONIEX Bids BTC_LTC [(0.01675001, 2.09268015), (0.01675, 570.39992889), (0.01674, 0.36715293), (0.01671115, 56.137), (0.01671114, 17.27164737)] ] - (poloniex.py:202||T=139726327990016)
01:21:11.785 - INFO - [ onUpdate POLONIEX Asks BTC_LTC [(0.01675003, 9.73645797), (0.01675467, 0.09975), (0.0167563, 0.0128042), (0.01675886, 0.74118139), (0.01676, 0.48728688)] ] - (poloniex.py:203||T=139726327990016)
01:21:13.191 - INFO - [ im here ] - (poloniex.py:180||T=139726327990016)
01:21:13.192 - INFO - [ onUpdate POLONIEX Asks BTC_LTC [(0.01675003, 9.73645797), (0.01675467, 0.09975), (0.0167563, 0.0128042), (0.01675886, 0.74118139), (0.01676, 0.48728688)] ] - (poloniex.py:233||T=139726327990016)
01:21:13.192 - INFO - [ im here ] - (poloniex.py:180||T=139726327990016)
01:21:13.192 - INFO - [ onUpdate POLONIEX Asks BTC_LTC [(0.01675003, 9.73645797), (0.01675467, 0.09975), (0.0167563, 0.0128042), (0.01675886, 0.74118139), (0.01676, 0.48728688)] ] - (poloniex.py:244||T=139726327990016)
01:21:13.192 - INFO - [ im here ] - (poloniex.py:180||T=139726327990016)
01:21:13.193 - INFO - [ onUpdate POLONIEX Asks BTC_LTC [(0.01675003, 9.73645797), (0.01675467, 0.09975), (0.0167563, 0.0128042), (0.01675886, 0.74118139), (0.01676, 0.48728688)] ] - (poloniex.py:233||T=139726327990016)
01:21:13.193 - INFO - [ im here ] - (poloniex.py:180||T=139726327990016)
01:21:13.193 - INFO - [ onUpdate POLONIEX Asks BTC_LTC [(0.01675003, 9.73645797), (0.01675467, 0.09975), (0.0167563, 0.0128042), (0.01675886, 0.74118139), (0.01676, 0.48728688)] ] - (poloniex.py:244||T=139726327990016)
01:21:13.193 - INFO - [ im here ] - (poloniex.py:180||T=139726327990016)
01:21:13.194 - INFO - [ onUpdate POLONIEX Bids USDT_BTC [(12111.76728038, 0.09633076), (12111.76728032, 0.15751211), (12111.76728024, 0.1), (12111.64616379, 0.012693), (12105.23020657, 0.69006721)] ] - (poloniex.py:248||T=139726327990016)
01:21:13.194 - INFO - [ im here ] - (poloniex.py:180||T=139726327990016)
01:21:13.194 - INFO - [ onUpdate POLONIEX Asks USDT_BTC [(12145.0, 0.65946432), (12149.99999996, 0.66701203), (12149.99999999, 0.94889392), (12150.0, 0.26492714), (12154.99999987, 0.46028193)] ] - (poloniex.py:233||T=139726327990016)
01:21:13.194 - INFO - [ im here ] - (poloniex.py:180||T=139726327990016)
01:21:13.195 - INFO - [ onUpdate POLONIEX Asks USDT_BTC [(12145.0, 0.65946432), (12149.99999996, 0.66701203), (12149.99999999, 0.94889392), (12150.0, 0.26492714), (12154.99999987, 0.46028193)] ] - (poloniex.py:244||T=139726327990016)
01:21:13.195 - INFO - [ im here ] - (poloniex.py:180||T=139726327990016)
01:21:13.195 - INFO - [ onUpdate POLONIEX Bids USDT_BTC [(12111.76728038, 0.09633076), (12111.76728032, 0.15751211), (12111.76728024, 0.1), (12111.64616379, 0.012693), (12105.23020657, 0.69006721)] ] - (poloniex.py:238||T=139726327990016)
01:21:13.196 - INFO - [ im here ] - (poloniex.py:180||T=139726327990016)
01:21:13.196 - INFO - [ onUpdate POLONIEX Bids USDT_BTC [(12111.76728038, 0.09633076), (12111.76728038, 0.07721202), (12111.76728032, 0.15751211), (12111.76728024, 0.1), (12111.64616379, 0.012693)] ] - (poloniex.py:248||T=139726327990016)
01:21:13.196 - INFO - [ im here ] - (poloniex.py:180||T=139726327990016)
01:21:13.196 - INFO - [ onUpdate POLONIEX TRADES USDT_BTC [u't', u'17103128', 0, u'12111.76728038', u'0.01911874', 1514654469] ] - (poloniex.py:223||T=139726327990016)
01:21:13.197 - INFO - [ im here ] - (poloniex.py:180||T=139726327990016)
01:21:13.197 - INFO - [ onUpdate POLONIEX Bids USDT_BTC [(12111.76728038, 0.09633076), (12111.76728038, 0.07721202), (12111.76728032, 0.15751211), (12111.76728024, 0.1)] ] - (poloniex.py:238||T=139726327990016)
01:21:13.197 - INFO - [ im here ] - (poloniex.py:180||T=139726327990016)
01:21:13.197 - INFO - [ onUpdate POLONIEX Asks BTC_LTC [(0.01675003, 9.73645797), (0.01675467, 0.09975), (0.0167563, 0.0128042), (0.01675886, 0.74118139), (0.01676, 0.48728688)] ] - (poloniex.py:233||T=139726327990016)
01:21:13.198 - INFO - [ im here ] - (poloniex.py:180||T=139726327990016)
01:21:13.198 - INFO - [ onUpdate POLONIEX Asks BTC_LTC [(0.01675003, 9.73645797), (0.01675467, 0.09975), (0.0167563, 0.0128042), (0.01675886, 0.74118139), (0.01676, 0.48728688)] ] - (poloniex.py:244||T=139726327990016)
01:21:13.198 - INFO - [ im here ] - (poloniex.py:180||T=139726327990016)
01:21:13.199 - INFO - [ onUpdate POLONIEX Asks BTC_LTC [(0.01675003, 9.73645797), (0.01675467, 0.09975), (0.0167563, 0.0128042), (0.01675886, 0.74118139), (0.01676, 0.48728688)] ] - (poloniex.py:233||T=139726327990016)
01:21:13.199 - INFO - [ im here ] - (poloniex.py:180||T=139726327990016)
01:21:13.199 - INFO - [ onUpdate POLONIEX Asks BTC_LTC [(0.01675003, 9.73645797), (0.01675467, 0.09975), (0.0167563, 0.0128042), (0.01675886, 0.74118139), (0.01676, 0.48728688)] ] - (poloniex.py:244||T=139726327990016)
01:21:13.199 - INFO - [ im here ] - (poloniex.py:180||T=139726327990016)
01:21:13.200 - INFO - [ onUpdate POLONIEX Asks USDT_BTC [(12145.0, 0.65946432), (12149.99999996, 0.66701203), (12149.99999999, 0.94889392), (12150.0, 0.26492714), (12154.99999987, 0.46028193)] ] - (poloniex.py:233||T=139726327990016)
01:21:13.200 - INFO - [ im here ] - (poloniex.py:180||T=139726327990016)
01:21:13.200 - INFO - [ onUpdate POLONIEX Asks USDT_BTC [(12145.0, 0.65946432), (12149.99999996, 0.66701203), (12149.99999999, 0.94889392), (12150.0, 0.26492714), (12154.99999987, 0.46028193)] ] - (poloniex.py:244||T=139726327990016)
01:21:13.200 - INFO - [ im here ] - (poloniex.py:180||T=139726327990016)
01:21:13.200 - INFO - [ onUpdate POLONIEX Bids USDT_BTC [(12111.76728038, 0.09633076), (12111.76728038, 0.07721202), (12111.76728032, 0.15751211), (12111.76728024, 0.1), (12075.36134791, 0.02)] ] - (poloniex.py:248||T=139726327990016)
01:21:13.201 - INFO - [ im here ] - (poloniex.py:180||T=139726327990016)
01:21:13.201 - INFO - [ onUpdate POLONIEX Bids USDT_BTC [(12111.76728038, 0.09633076), (12111.76728038, 0.07721202), (12111.76728032, 0.15751211), (12111.76728024, 0.1), (12111.64616379, 0.012693)] ] - (poloniex.py:248||T=139726327990016)
01:21:13.201 - INFO - [ im here ] - (poloniex.py:180||T=139726327990016)
01:21:13.202 - INFO - [ onUpdate POLONIEX Asks USDT_BTC [(12145.0, 0.65946432), (12149.99999996, 0.66701203), (12149.99999999, 0.94889392), (12150.0, 0.26492714), (12154.99999987, 0.46028193)] ] - (poloniex.py:244||T=139726327990016)
01:21:13.202 - INFO - [ im here ] - (poloniex.py:180||T=139726327990016)
01:21:13.202 - INFO - [ onUpdate POLONIEX Bids USDT_BTC [(12111.76728038, 0.09633076), (12111.76728038, 0.07721202), (12111.76728038, 0.0770932), (12111.76728032, 0.15751211), (12111.76728024, 0.1)] ] - (poloniex.py:248||T=139726327990016)
01:21:13.202 - INFO - [ im here ] - (poloniex.py:180||T=139726327990016)
01:21:13.202 - INFO - [ onUpdate POLONIEX TRADES USDT_BTC [u't', u'17103129', 0, u'12111.76728038', u'0.00011882', 1514654470] ] - (poloniex.py:223||T=139726327990016)
01:21:13.203 - INFO - [ im here ] - (poloniex.py:180||T=139726327990016)
01:21:13.203 - INFO - [ onUpdate POLONIEX Asks USDT_BTC [(12145.0, 0.65946432), (12149.99999996, 0.66701203), (12149.99999999, 0.94889392), (12150.0, 0.26492714), (12154.99999987, 0.46028193)] ] - (poloniex.py:244||T=139726327990016)
